Workbook
Name SegmentaciónDeDatos_genres___Clean: #N/A
Name SegmentaciónDeDatos_Grupo_Edad: #N/A
Name SegmentaciónDeDatos_IMDb_Tier1: #N/A
Name SegmentaciónDeDatos_production_countries___Clean: #N/A
Name SegmentaciónDeDatos_type: #N/A
Name Timeline_Fecha_Timeline: #N/A

Sheet Datos limpios
A1: id | B1: title | C1: type | D1: description | E1: release_year | F1: age_certification | G1: runtime_HHMM | H1: runtime | I1: genres | J1: genres - Clean | K1: production_countries - Clean | L1: production_countries | M1: seasons | N1: imdb_id | O1: imdb_score | P1: imdb_votes | Q1: tmdb_popularity | R1: tmdb_score
A2: ts300399 | B2: Five Came Back: The Reference Films | C2: SHOW | D2: This collection includes 12 World War II-era propaganda films — many of which are graphic and offensive — discussed in the docuseries "Five Came Back." | E2: 1945 | F2: TV-MA | G2: 00:51 | H2: 51 | I2: ['documentation'] | J2: documentation | K2: US | L2: ['US'] | M2: 1.0 | Q2: 0.6
A3: tm84618 | B3: Taxi Driver | C3: MOVIE | D3: A mentally unstable Vietnam War veteran works as a night-time taxi driver in New York City where the perceived decadence and sleaze feed his urge for violent action. | E3: 1976 | F3: R | G3: 01:54 | H3: 114 | I3: ['drama', 'crime'] | J3: drama | K3: US | L3: ['US'] | N3: tt0075314 | O3: 8.2 | P3: 808582 | Q3: 40.965 | R3: 8.179
A4: tm84618 | B4: Taxi Driver | C4: MOVIE | D4: A mentally unstable Vietnam War veteran works as a night-time taxi driver in New York City where the perceived decadence and sleaze feed his urge for violent action. | E4: 1976 | F4: R | G4: 01:54 | H4: 114 | I4: ['drama', 'crime'] | J4: crime | K4: US | L4: ['US'] | N4: tt0075314 | O4: 8.2 | P4: 808582 | Q4: 40.965 | R4: 8.179
A5: tm154986 | B5: Deliverance | C5: MOVIE | D5: Intent on seeing the Cahulawassee River before it's turned into one huge lake, outdoor fanatic Lewis Medlock takes his friends on a river-rafting trip they'll never forget into the dangerous American back-country. | E5: 1972 | F5: R | G5: 01:49 | H5: 109 | I5: ['drama', 'action', 'thriller', 'european'] | J5: drama | K5: US | L5: ['US'] | N5: tt0068473 | O5: 7.7 | P5: 107673 | Q5: 10.01 | R5: 7.3
A6: tm154986 | B6: Deliverance | C6: MOVIE | D6: Intent on seeing the Cahulawassee River before it's turned into one huge lake, outdoor fanatic Lewis Medlock takes his friends on a river-rafting trip they'll never forget into the dangerous American back-country. | E6: 1972 | F6: R | G6: 01:49 | H6: 109 | I6: ['drama', 'action', 'thriller', 'european'] | J6: action | K6: US | L6: ['US'] | N6: tt0068473 | O6: 7.7 | P6: 107673 | Q6: 10.01 | R6: 7.3
A7: tm154986 | B7: Deliverance | C7: MOVIE | D7: Intent on seeing the Cahulawassee River before it's turned into one huge lake, outdoor fanatic Lewis Medlock takes his friends on a river-rafting trip they'll never forget into the dangerous American back-country. | E7: 1972 | F7: R | G7: 01:49 | H7: 109 | I7: ['drama', 'action', 'thriller', 'european'] | J7: thriller | K7: US | L7: ['US'] | N7: tt0068473 | O7: 7.7 | P7: 107673 | Q7: 10.01 | R7: 7.3
A8: tm154986 | B8: Deliverance | C8: MOVIE | D8: Intent on seeing the Cahulawassee River before it's turned into one huge lake, outdoor fanatic Lewis Medlock takes his friends on a river-rafting trip they'll never forget into the dangerous American back-country. | E8: 1972 | F8: R | G8: 01:49 | H8: 109 | I8: ['drama', 'action', 'thriller', 'european'] | J8: european | K8: US | L8: ['US'] | N8: tt0068473 | O8: 7.7 | P8: 107673 | Q8: 10.01 | R8: 7.3
A9: tm127384 | B9: Monty Python and the Holy Grail | C9: MOVIE | D9: King Arthur, accompanied by his squire, recruits his Knights of the Round Table, including Sir Bedevere the Wise, Sir Lancelot the Brave, Sir Robin the Not-Quite-So-Brave-As-Sir-Lancelot and Sir Galahad the Pure. On the way, Arthur battles the Black Knight who, despite having had all his limbs chopped off, insists he can still fight. They reach Camelot, but Arthur decides not to enter, as "it is a silly place". | E9: 1975 | F9: PG | G9: 01:31 | H9: 91 | I9: ['fantasy', 'action', 'comedy'] | J9: fantasy | K9: GB | L9: ['GB'] | N9: tt0071853 | O9: 8.2 | P9: 534486 | Q9: 15.461 | R9: 7.811
A10: tm127384 | B10: Monty Python and the Holy Grail | C10: MOVIE | D10: King Arthur, accompanied by his squire, recruits his Knights of the Round Table, including Sir Bedevere the Wise, Sir Lancelot the Brave, Sir Robin the Not-Quite-So-Brave-As-Sir-Lancelot and Sir Galahad the Pure. On the way, Arthur battles the Black Knight who, despite having had all his limbs chopped off, insists he can still fight. They reach Camelot, but Arthur decides not to enter, as "it is a silly place". | E10: 1975 | F10: PG | G10: 01:31 | H10: 91 | I10: ['fantasy', 'action', 'comedy'] | J10: action | K10: GB | L10: ['GB'] | N10: tt0071853 | O10: 8.2 | P10: 534486 | Q10: 15.461 | R10: 7.811
A11: tm127384 | B11: Monty Python and the Holy Grail | C11: MOVIE | D11: King Arthur, accompanied by his squire, recruits his Knights of the Round Table, including Sir Bedevere the Wise, Sir Lancelot the Brave, Sir Robin the Not-Quite-So-Brave-As-Sir-Lancelot and Sir Galahad the Pure. On the way, Arthur battles the Black Knight who, despite having had all his limbs chopped off, insists he can still fight. They reach Camelot, but Arthur decides not to enter, as "it is a silly place". | E11: 1975 | F11: PG | G11: 01:31 | H11: 91 | I11: ['fantasy', 'action', 'comedy'] | J11: comedy | K11: GB | L11: ['GB'] | N11: tt0071853 | O11: 8.2 | P11: 534486 | Q11: 15.461 | R11: 7.811
A12: tm120801 | B12: The Dirty Dozen | C12: MOVIE | D12: 12 American military prisoners in World War II are ordered to infiltrate a well-guarded enemy château and kill the Nazi officers vacationing there. The soldiers, most of whom are facing death sentences for a variety of violent crimes, agree to the mission and the possible commuting of their sentences. | E12: 1967 | F12: NO INFORMADO | G12: 02:30 | H12: 150 | I12: ['war', 'action'] | J12: war | K12: GB | L12: ['GB', 'US'] | N12: tt0061578 | O12: 7.7 | P12: 72662 | Q12: 20.398 | R12: 7.6
A13: tm120801 | B13: The Dirty Dozen | C13: MOVIE | D13: 12 American military prisoners in World War II are ordered to infiltrate a well-guarded enemy château and kill the Nazi officers vacationing there. The soldiers, most of whom are facing death sentences for a variety of violent crimes, agree to the mission and the possible commuting of their sentences. | E13: 1967 | F13: NO INFORMADO | G13: 02:30 | H13: 150 | I13: ['war', 'action'] | J13: war | K13: US | L13: ['GB', 'US'] | N13: tt0061578 | O13: 7.7 | P13: 72662 | Q13: 20.398 | R13: 7.6
A14: tm120801 | B14: The Dirty Dozen | C14: MOVIE | D14: 12 American military prisoners in World War II are ordered to infiltrate a well-guarded enemy château and kill the Nazi officers vacationing there. The soldiers, most of whom are facing death sentences for a variety of violent crimes, agree to the mission and the possible commuting of their sentences. | E14: 1967 | F14: NO INFORMADO | G14: 02:30 | H14: 150 | I14: ['war', 'action'] | J14: action | K14: GB | L14: ['GB', 'US'] | N14: tt0061578 | O14: 7.7 | P14: 72662 | Q14: 20.398 | R14: 7.6
A15: tm120801 | B15: The Dirty Dozen | C15: MOVIE | D15: 12 American military prisoners in World War II are ordered to infiltrate a well-guarded enemy château and kill the Nazi officers vacationing there. The soldiers, most of whom are facing death sentences for a variety of violent crimes, agree to the mission and the possible commuting of their sentences. | E15: 1967 | F15: NO INFORMADO | G15: 02:30 | H15: 150 | I15: ['war', 'action'] | J15: action | K15: US | L15: ['GB', 'US'] | N15: tt0061578 | O15: 7.7 | P15: 72662 | Q15: 20.398 | R15: 7.6
A16: ts22164 | B16: Monty Python's Flying Circus | C16: SHOW | D16: A British sketch comedy series with the shows being composed of surreality, risqué or innuendo-laden humour, sight gags and observational sketches without punchlines. | E16: 1969 | F16: TV-14 | G16: 00:30 | H16: 30 | I16: ['comedy', 'european'] | J16: comedy | K16: GB | L16: ['GB'] | M16: 4.0 | N16: tt0063929 | O16: 8.8 | P16: 73424 | Q16: 17.617 | R16: 8.306
A17: ts22164 | B17: Monty Python's Flying Circus | C17: SHOW | D17: A British sketch comedy series with the shows being composed of surreality, risqué or innuendo-laden humour, sight gags and observational sketches without punchlines. | E17: 1969 | F17: TV-14 | G17: 00:30 | H17: 30 | I17: ['comedy', 'european'] | J17: european | K17: GB | L17: ['GB'] | M17: 4.0 | N17: tt0063929 | O17: 8.8 | P17: 73424 | Q17: 17.617 | R17: 8.306
A18: tm70993 | B18: Life of Brian | C18: MOVIE | D18: Brian Cohen is an average young Jewish man, but through a series of ridiculous events, he gains a reputation as the Messiah. When he's not dodging his followers or being scolded by his shrill mother, the hapless Brian has to contend with the pompous Pontius Pilate and acronym-obsessed members of a separatist movement. Rife with Monty Python's signature absurdity, the tale finds Brian's life paralleling Biblical lore, albeit with many more laughs. | E18: 1979 | F18: R | G18: 01:34 | H18: 94 | I18: ['comedy'] | J18: comedy | K18: GB | L18: ['GB'] | N18: tt0079470 | O18: 8 | P18: 395024 | Q18: 17.77 | R18: 7.8
A19: tm14873 | B19: Dirty Harry | C19: MOVIE | D19: When a madman dubbed 'Scorpio' terrorizes San Francisco, hard-nosed cop, Harry Callahan – famous for his take-no-prisoners approach to law enforcement – is tasked with hunting down the psychopath. Harry eventually collars Scorpio in the process of rescuing a kidnap victim, only to see him walk on technicalities. Now, the maverick detective is determined to nail the maniac himself. | E19: 1971 | F19: R | G19: 01:42 | H19: 102 | I19: ['thriller', 'action', 'crime'] | J19: thriller | K19: US | L19: ['US'] | N19: tt0066999 | O19: 7.7 | P19: 155051 | Q19: 12.817 | R19: 7.5
A20: tm14873 | B20: Dirty Harry | C20: MOVIE | D20: When a madman dubbed 'Scorpio' terrorizes San Francisco, hard-nosed cop, Harry Callahan – famous for his take-no-prisoners approach to law enforcement – is tasked with hunting down the psychopath. Harry eventually collars Scorpio in the process of rescuing a kidnap victim, only to see him walk on technicalities. Now, the maverick detective is determined to nail the maniac himself. | E20: 1971 | F20: R | G20: 01:42 | H20: 102 | I20: ['thriller', 'action', 'crime'] | J20: action | K20: US | L20: ['US'] | N20: tt0066999 | O20: 7.7 | P20: 155051 | Q20: 12.817 | R20: 7.5
A21: tm14873 | B21: Dirty Harry | C21: MOVIE | D21: When a madman dubbed 'Scorpio' terrorizes San Francisco, hard-nosed cop, Harry Callahan – famous for his take-no-prisoners approach to law enforcement – is tasked with hunting down the psychopath. Harry eventually collars Scorpio in the process of rescuing a kidnap victim, only to see him walk on technicalities. Now, the maverick detective is determined to nail the maniac himself. | E21: 1971 | F21: R | G21: 01:42 | H21: 102 | I21: ['thriller', 'action', 'crime'] | J21: crime | K21: US | L21: ['US'] | N21: tt0066999 | O21: 7.7 | P21: 155051 | Q21: 12.817 | R21: 7.5
A22: tm119281 | B22: Bonnie and Clyde | C22: MOVIE | D22: In the 1930s, bored waitress Bonnie Parker falls in love with an ex-con named Clyde Barrow and together they start a violent crime spree through the country, stealing cars and robbing banks. | E22: 1967 | F22: R | G22: 01:50 | H22: 110 | I22: ['crime', 'drama', 'action'] | J22: crime | K22: US | L22: ['US'] | N22: tt0061418 | O22: 7.7 | P22: 112048 | Q22: 15.687 | R22: 7.5
A23: tm119281 | B23: Bonnie and Clyde | C23: MOVIE | D23: In the 1930s, bored waitress Bonnie Parker falls in love with an ex-con named Clyde Barrow and together they start a violent crime spree through the country, stealing cars and robbing banks. | E23: 1967 | F23: R | G23: 01:50 | H23: 110 | I23: ['crime', 'drama', 'action'] | J23: drama | K23: US | L23: ['US'] | N23: tt0061418 | O23: 7.7 | P23: 112048 | Q23: 15.687 | R23: 7.5
A24: tm119281 | B24: Bonnie and Clyde | C24: MOVIE | D24: In the 1930s, bored waitress Bonnie Parker falls in love with an ex-con named Clyde Barrow and together they start a violent crime spree through the country, stealing cars and robbing banks. | E24: 1967 | F24: R | G24: 01:50 | H24: 110 | I24: ['crime', 'drama', 'action'] | J24: action | K24: US | L24: ['US'] | N24: tt0061418 | O24: 7.7 | P24: 112048 | Q24: 15.687 | R24: 7.5
A25: tm98978 | B25: The Blue Lagoon | C25: MOVIE | D25: Two small children and a ship's cook survive a shipwreck and find safety on an idyllic tropical island. Soon, however, the cook dies and the young boy and girl are left on their own. Days become years and Emmeline and Richard make a home for themselves surrounded by exotic creatures and nature's beauty. But will they ever see civilization again? | E25: 1980 | F25: R | G25: 01:44 | H25: 104 | I25: ['romance', 'action', 'drama'] | J25: romance | K25: US | L25: ['US'] | N25: tt0080453 | O25: 5.8 | P25: 69844 | Q25: 50.324 | R25: 6.156
A26: tm98978 | B26: The Blue Lagoon | C26: MOVIE | D26: Two small children and a ship's cook survive a shipwreck and find safety on an idyllic tropical island. Soon, however, the cook dies and the young boy and girl are left on their own. Days become years and Emmeline and Richard make a home for themselves surrounded by exotic creatures and nature's beauty. But will they ever see civilization again? | E26: 1980 | F26: R | G26: 01:44 | H26: 104 | I26: ['romance', 'action', 'drama'] | J26: action | K26: US | L26: ['US'] | N26: tt0080453 | O26: 5.8 | P26: 69844 | Q26: 50.324 | R26: 6.156
A27: tm98978 | B27: The Blue Lagoon | C27: MOVIE | D27: Two small children and a ship's cook survive a shipwreck and find safety on an idyllic tropical island. Soon, however, the cook dies and the young boy and girl are left on their own. Days become years and Emmeline and Richard make a home for themselves surrounded by exotic creatures and nature's beauty. But will they ever see civilization again? | E27: 1980 | F27: R | G27: 01:44 | H27: 104 | I27: ['romance', 'action', 'drama'] | J27: drama | K27: US | L27: ['US'] | N27: tt0080453 | O27: 5.8 | P27: 69844 | Q27: 50.324 | R27: 6.156
A28: tm44204 | B28: The Guns of Navarone | C28: MOVIE | D28: A team of allied saboteurs are assigned an impossible mission: infiltrate an impregnable Nazi-held island and destroy the two enormous long-range field guns that prevent the rescue of 2,000 trapped British soldiers. | E28: 1961 | F28: NO INFORMADO | G28: 02:38 | H28: 158 | I28: ['action', 'drama', 'war'] | J28: action | K28: GB | L28: ['GB', 'US'] | N28: tt0054953 | O28: 7.5 | P28: 50748 | Q28: 13.844 | R28: 7.3
A29: tm44204 | B29: The Guns of Navarone | C29: MOVIE | D29: A team of allied saboteurs are assigned an impossible mission: infiltrate an impregnable Nazi-held island and destroy the two enormous long-range field guns that prevent the rescue of 2,000 trapped British soldiers. | E29: 1961 | F29: NO INFORMADO | G29: 02:38 | H29: 158 | I29: ['action', 'drama', 'war'] | J29: action | K29: US | L29: ['GB', 'US'] | N29: tt0054953 | O29: 7.5 | P29: 50748 | Q29: 13.844 | R29: 7.3
... A107: tm16812 | B107: Bandie | C107: MOVIE | D107: Maharaj Brajbhan lives a wealthy lifestyle in Bharatpur, India along with his wife, Badi Rani, but have been unable to conceive for Bharatpur, and have no choice but to leave it's reigns with Brajban's widowed cousin, Vikram, and his son, Kanchan. When Vikram finds out that Badi Rani is pregnant, he plots to first sully her character by having her abducted, then shunned by the Maharaj, and then decides to have her killed. But her killer has a change of heart and lets her live. She gives birth to a son, names him Bhola, and starts living a simple lifestyle in a Mandir with the help of it's Poojary. Years later Vikram finds out she is alive and kills her, as well the Poojary and the Poojary's son. Bhola witnesses this, manages to escape, starts to live with a poor widow, grows up uneducated, and makes a living through crime. | E107: 1978 | F107: NO INFORMADO | G107: 02:21 | H107: 141 | I107: ['drama', 'action', 'romance'] | J107: romance | K107: IN | L107: ['IN'] | N107: tt1219315 | O107: 4.4 | P107: 35 | Q107: 1.166 | R107: 6
A108: ts20681 | B108: Seinfeld | C108: SHOW | D108: A stand-up comedian and his three offbeat friends weather the pitfalls and payoffs of life in New York City in the '90s. It's a show about nothing. | E108: 1989 | F108: TV-PG | G108: 00:24 | H108: 24 | I108: ['comedy'] | J108: comedy | K108: US | L108: ['US'] | M108: 9.0 | N108: tt0098904 | O108: 8.9 | P108: 308824 | Q108: 130.213 | R108: 8.301
A109: tm155787 | B109: GoodFellas | C109: MOVIE | D109: The true story of Henry Hill, a half-Irish, half-Sicilian Brooklyn kid who is adopted by neighbourhood gangsters at an early age and climbs the ranks of a Mafia family under the guidance of Jimmy Conway. | E109: 1990 | F109: R | G109: 02:25 | H109: 145 | I109: ['drama', 'crime'] | J109: drama | K109: US | L109: ['US'] | N109: tt0099685 | O109: 8.7 | P109: 1131681 | Q109: 50.387 | R109: 8.463
A110: tm155787 | B110: GoodFellas | C110: MOVIE | D110: The true story of Henry Hill, a half-Irish, half-Sicilian Brooklyn kid who is adopted by neighbourhood gangsters at an early age and climbs the ranks of a Mafia family under the guidance of Jimmy Conway. | E110: 1990 | F110: R | G110: 02:25 | H110: 145 | I110: ['drama', 'crime'] | J110: crime | K110: US | L110: ['US'] | N110: tt0099685 | O110: 8.7 | P110: 1131681 | Q110: 50.387 | R110: 8.463
A111: tm22327 | B111: Full Metal Jacket | C111: MOVIE | D111: A pragmatic U.S. Marine observes the dehumanizing effects the U.S.-Vietnam War has on his fellow recruits from their brutal boot camp training to the bloody street fighting in Hue. | E111: 1987 | F111: R | G111: 01:57 | H111: 117 | I111: ['war', 'drama'] | J111: war | K111: US | L111: ['US', 'GB'] | N111: tt0093058 | O111: 8.3 | P111: 729274 | Q111: 32.937 | R111: 8.1
A112: tm22327 | B112: Full Metal Jacket | C112: MOVIE | D112: A pragmatic U.S. Marine observes the dehumanizing effects the U.S.-Vietnam War has on his fellow recruits from their brutal boot camp training to the bloody street fighting in Hue. | E112: 1987 | F112: R | G112: 01:57 | H112: 117 | I112: ['war', 'drama'] | J112: war | K112: GB | L112: ['US', 'GB'] | N112: tt0093058 | O112: 8.3 | P112: 729274 | Q112: 32.937 | R112: 8.1
A113: tm22327 | B113: Full Metal Jacket | C113: MOVIE | D113: A pragmatic U.S. Marine observes the dehumanizing effects the U.S.-Vietnam War has on his fellow recruits from their brutal boot camp training to the bloody street fighting in Hue. | E113: 1987 | F113: R | G113: 01:57 | H113: 117 | I113: ['war', 'drama'] | J113: drama | K113: US | L113: ['US', 'GB'] | N113: tt0093058 | O113: 8.3 | P113: 729274 | Q113: 32.937 | R113: 8.1
A114: tm22327 | B114: Full Metal Jacket | C114: MOVIE | D114: A pragmatic U.S. Marine observes the dehumanizing effects the U.S.-Vietnam War has on his fellow recruits from their brutal boot camp training to the bloody street fighting in Hue. | E114: 1987 | F114: R | G114: 01:57 | H114: 117 | I114: ['war', 'drama'] | J114: drama | K114: GB | L114: ['US', 'GB'] | N114: tt0093058 | O114: 8.3 | P114: 729274 | Q114: 32.937 | R114: 8.1
A115: tm180542 | B115: Once Upon a Time in America | C115: MOVIE | D115: A former Prohibition-era Jewish gangster returns to the Lower East Side of Manhattan over thirty years later, where he once again must confront the ghosts and regrets of his old life. | E115: 1984 | F115: R | G115: 02:19 | H115: 139 | I115: ['crime', 'drama', 'european'] | J115: crime | K115: US | L115: ['US', 'IT'] | N115: tt0087843 | O115: 8.3 | P115: 345714 | Q115: 28.937 | R115: 8.453
A116: tm180542 | B116: Once Upon a Time in America | C116: MOVIE | D116: A former Prohibition-era Jewish gangster returns to the Lower East Side of Manhattan over thirty years later, where he once again must confront the ghosts and regrets of his old life. | E116: 1984 | F116: R | G116: 02:19 | H116: 139 | I116: ['crime', 'drama', 'european'] | J116: crime | K116: IT | L116: ['US', 'IT'] | N116: tt0087843 | O116: 8.3 | P116: 345714 | Q116: 28.937 | R116: 8.453
A117: tm180542 | B117: Once Upon a Time in America | C117: MOVIE | D117: A former Prohibition-era Jewish gangster returns to the Lower East Side of Manhattan over thirty years later, where he once again must confront the ghosts and regrets of his old life. | E117: 1984 | F117: R | G117: 02:19 | H117: 139 | I117: ['crime', 'drama', 'european'] | J117: drama | K117: US | L117: ['US', 'IT'] | N117: tt0087843 | O117: 8.3 | P117: 345714 | Q117: 28.937 | R117: 8.453
...

Sheet Tablas dinámicas
A3: Títulos | B3: IMDb medio | C3: TMDb medio | D3: Popularidad media | E3: Duración media
A4: 5577 | B4: 6.5179645 | C4: 6.8318808 | D4: 23.146124 | E4: 77.861036
A9: Etiquetas de fila | B9: Títulos
A10: MOVIE | B10: 3561
A11: SHOW | B11: 2016
A12: Total general | B12: 5577
B15: Títulos | D15: Etiquetas de fila | E15: Títulos | F15: Etiquetas de fila | G15: Títulos | H15: Etiquetas de fila | I15: Títulos | J15: Etiquetas de fila | K15: Títulos | O15: Etiquetas de fila | P15: Títulos | U15: Etiquetas de fila | V15: Duración media | W15: IMDb medio | X15: Votos IMDb | Y15: Temporadas
A16: 2012 | B16: 106 | D16: drama | E16: 2927 | F16: US | G16: 2303 | H16: G | I16: 110 | J16: 1 Infantil | K16: 207 | O16: Excelente | P16: 479 | U16: Breaking Bad | V16: 48 | W16: 9.5 | X16: 1775990 | Y16: 3
A17: 2013 | B17: 130 | D17: comedy | E17: 2235 | F17: IN | G17: 621 | H17: NC-17 | I17: 16 | J17: 2 Familiar | K17: 592 | O17: Muy buena | P17: 1539 | U17: Our Planet | V17: 50 | W17: 9.3 | X17: 42259 | Y17: 1
A18: 2014 | B18: 150 | D18: thriller | E18: 1213 | F18: GB | G18: 404 | H18: NO INFORMADO | I18: 2442 | J18: 3 Adolescentes | K18: 904 | O18: Buena | P18: 1699 | U18: Avatar: The Last Airbender | V18: 24 | W18: 9.3 | X18: 303666 | Y18: 5
A19: 2015 | B19: 218 | D19: action | E19: 1143 | F19: JP | G19: 282 | H19: PG | I19: 230 | J19: 4 Adultos | K19: 550 | O19: Regular | P19: 1003 | U19: Reply 1988 | V19: 92 | W19: 9.2 | X19: 6718 | Y19: 4
A20: 2016 | B20: 360 | D20: romance | E20: 959 | F20: FR | G20: 247 | H20: PG-13 | I20: 444 | J20: 5 Adultos con reparos | K20: 882 | O20: Baja | P20: 468 | U20: Kota Factory | V20: 39 | W20: 9.1 | X20: 69316 | Y20: 2
A21: 2017 | B21: 551 | D21: crime | E21: 925 | F21: KR | G21: 222 | H21: R | I21: 550 | J21: 6 Sin clasificar | K21: 2442 | O21: Sin valoración | P21: 389
A22: 2018 | B22: 741 | D22: documentation | E22: 898 | F22: CA | G22: 216 | H22: TV-14 | I22: 460 | J22: Total general | K22: 5577
A23: 2019 | B23: 790 | D23: animation | E23: 657 | F23: ES | G23: 210 | H23: TV-G | I23: 77
A24: 2020 | B24: 757 | D24: family | E24: 655 | F24: DE | G24: 139 | H24: TV-MA | I24: 866
A25: 2021 | B25: 726 | D25: fantasy | E25: 622 | F25: MX | G25: 126 | H25: TV-PG | I25: 175
A26: 2022 | B26: 336 | D26: scifi | E26: 581 | F26: CN | G26: 102 | H26: TV-Y | I26: 95
A27: Total general | B27: 4865 | D27: european | E27: 443 | F27: BR | G27: 101 | H27: TV-Y7 | I27: 112
D28: horror | E28: 373 | F28: PH | G28: 86 | H28: Total general | I28: 5577
D29: music | E29: 251 | F29: TR | G29: 84
D30: history | E30: 250 | F30: AU | G30: 84
D31: reality | E31: 216 | F31: IT | G31: 83
D32: sport | E32: 169 | F32: NG | G32: 73
D33: war | E33: 163 | F33: AR | G33: 72
D34: western | E34: 41 | F34: TW | G34: 64
D35: Total general | E35: 5577 | F35: ID | G35: 62

Sheet DASHBOARD
A1: CLASIFICACIÓN
A13: VALORACIÓN
J16: TITULO | K16: DUR. | L16: IMDB | M16: VOTOS | N16: TEMP.
I17: 1 | J17: ='Tablas dinámicas'!U16 -> Breaking Bad | K17: ='Tablas dinámicas'!V16 -> 48 | L17: ='Tablas dinámicas'!W16 -> 9.5 | M17: ='Tablas dinámicas'!X16 -> 1775990 | N17: ='Tablas dinámicas'!Y16 -> 3
I18: 2 | J18: ='Tablas dinámicas'!U17 -> Our Planet | K18: ='Tablas dinámicas'!V17 -> 50 | L18: ='Tablas dinámicas'!W17 -> 9.3 | M18: ='Tablas dinámicas'!X17 -> 42259 | N18: ='Tablas dinámicas'!Y17 -> 1
I19: 3 | J19: ='Tablas dinámicas'!U18 -> Avatar: The Last Airbender | K19: ='Tablas dinámicas'!V18 -> 24 | L19: ='Tablas dinámicas'!W18 -> 9.3 | M19: ='Tablas dinámicas'!X18 -> 303666 | N19: ='Tablas dinámicas'!Y18 -> 5
I20: 4 | J20: ='Tablas dinámicas'!U19 -> Reply 1988 | K20: ='Tablas dinámicas'!V19 -> 92 | L20: ='Tablas dinámicas'!W19 -> 9.2 | M20: ='Tablas dinámicas'!X19 -> 6718 | N20: ='Tablas dinámicas'!Y19 -> 4
I21: 5 | J21: ='Tablas dinámicas'!U20 -> Kota Factory | K21: ='Tablas dinámicas'!V20 -> 39 | L21: ='Tablas dinámicas'!W20 -> 9.1 | M21: ='Tablas dinámicas'!X20 -> 69316 | N21: ='Tablas dinámicas'!Y20 -> 2
A26: GENERO

Sheet encabezados
A1: id
A2: title
A3: type
A4: description
A5: release_year
A6: age_certification
A7: runtime_HHMM
A8: runtime
A9: genres
A10: genres - Clean
A11: production_countries - Clean
A12: production_countries
... A19: seasons_clean

Sheet DIMENSIONES
A1: IMDb_Tier_Filtro
A2: Excelente
A3: Muy buena
A4: Buena
A5: Regular
A6: Baja
